supervisor: couldn't exec /web/activities/mobileapps/run.sh: ENOEXEC
supervisor: child process was not spawned
supervisor: couldn't exec /web/activities/mobileapps/run.sh: ENOEXEC
supervisor: child process was not spawned
supervisor: couldn't exec /web/activities/mobileapps/run.sh: ENOEXEC
supervisor: child process was not spawned
supervisor: couldn't exec /web/activities/mobileapps/run.sh: ENOEXEC
supervisor: child process was not spawned
supervisor: couldn't exec /web/activities/mobileapps/run.sh: ENOEXEC
supervisor: child process was not spawned
supervisor: couldn't exec /web/activities/mobileapps/run.sh: ENOEXEC
supervisor: child process was not spawned
supervisor: couldn't exec /web/activities/mobileapps/run.sh: ENOEXEC
supervisor: child process was not spawned
supervisor: couldn't exec /web/activities/mobileapps/run.sh: ENOEXEC
supervisor: child process was not spawned
supervisor: couldn't exec /web/activities/mobileapps/run.sh: ENOEXEC
supervisor: child process was not spawned
supervisor: couldn't exec /web/activities/mobileapps/run.sh: ENOEXEC
supervisor: child process was not spawned
supervisor: couldn't exec /web/activities/mobileapps/run.sh: ENOEXEC
supervisor: child process was not spawned
supervisor: couldn't exec /web/activities/mobileapps/run.sh: ENOEXEC
supervisor: child process was not spawned
[2020-06-21 18:15:16 -0400] [32311] [INFO] Starting gunicorn 20.0.0
[2020-06-21 18:15:16 -0400] [32311] [INFO] Listening at: http://127.0.0.1:10831 (32311)
[2020-06-21 18:15:16 -0400] [32311] [INFO] Using worker: sync
[2020-06-21 18:15:16 -0400] [32320] [INFO] Booting worker with pid: 32320
[2020-06-21 18:15:16 -0400] [32320] [ERROR] Exception in worker process
Traceback (most recent call last):
  File "/usr/local/lib/python3.5/dist-packages/gunicorn/arbiter.py", line 583, in spawn_worker
    worker.init_process()
  File "/usr/local/lib/python3.5/dist-packages/gunicorn/workers/base.py", line 133, in init_process
    self.load_wsgi()
  File "/usr/local/lib/python3.5/dist-packages/gunicorn/workers/base.py", line 142, in load_wsgi
    self.wsgi = self.app.wsgi()
  File "/usr/local/lib/python3.5/dist-packages/gunicorn/app/base.py", line 67, in wsgi
    self.callable = self.load()
  File "/usr/local/lib/python3.5/dist-packages/gunicorn/app/wsgiapp.py", line 49, in load
    return self.load_wsgiapp()
  File "/usr/local/lib/python3.5/dist-packages/gunicorn/app/wsgiapp.py", line 39, in load_wsgiapp
    return util.import_app(self.app_uri)
  File "/usr/local/lib/python3.5/dist-packages/gunicorn/util.py", line 331, in import_app
    mod = importlib.import_module(module)
  File "/usr/lib/python3.5/importlib/__init__.py", line 126, in import_module
    return _bootstrap._gcd_import(name[level:], package, level)
  File "<frozen importlib._bootstrap>", line 986, in _gcd_import
  File "<frozen importlib._bootstrap>", line 969, in _find_and_load
  File "<frozen importlib._bootstrap>", line 956, in _find_and_load_unlocked
ImportError: No module named 'server'
[2020-06-21 18:15:16 -0400] [32320] [INFO] Worker exiting (pid: 32320)
[2020-06-21 18:15:16 -0400] [32311] [INFO] Shutting down: Master
[2020-06-21 18:15:16 -0400] [32311] [INFO] Reason: Worker failed to boot.
[2020-06-21 18:15:19 -0400] [32516] [INFO] Starting gunicorn 20.0.0
[2020-06-21 18:15:19 -0400] [32516] [INFO] Listening at: http://127.0.0.1:10831 (32516)
[2020-06-21 18:15:19 -0400] [32516] [INFO] Using worker: sync
[2020-06-21 18:15:19 -0400] [32585] [INFO] Booting worker with pid: 32585
[2020-06-21 18:15:19 -0400] [32585] [ERROR] Exception in worker process
Traceback (most recent call last):
  File "/usr/local/lib/python3.5/dist-packages/gunicorn/arbiter.py", line 583, in spawn_worker
    worker.init_process()
  File "/usr/local/lib/python3.5/dist-packages/gunicorn/workers/base.py", line 133, in init_process
    self.load_wsgi()
  File "/usr/local/lib/python3.5/dist-packages/gunicorn/workers/base.py", line 142, in load_wsgi
    self.wsgi = self.app.wsgi()
  File "/usr/local/lib/python3.5/dist-packages/gunicorn/app/base.py", line 67, in wsgi
    self.callable = self.load()
  File "/usr/local/lib/python3.5/dist-packages/gunicorn/app/wsgiapp.py", line 49, in load
    return self.load_wsgiapp()
  File "/usr/local/lib/python3.5/dist-packages/gunicorn/app/wsgiapp.py", line 39, in load_wsgiapp
    return util.import_app(self.app_uri)
  File "/usr/local/lib/python3.5/dist-packages/gunicorn/util.py", line 331, in import_app
    mod = importlib.import_module(module)
  File "/usr/lib/python3.5/importlib/__init__.py", line 126, in import_module
    return _bootstrap._gcd_import(name[level:], package, level)
  File "<frozen importlib._bootstrap>", line 986, in _gcd_import
  File "<frozen importlib._bootstrap>", line 969, in _find_and_load
  File "<frozen importlib._bootstrap>", line 956, in _find_and_load_unlocked
ImportError: No module named 'server'
[2020-06-21 18:15:19 -0400] [32585] [INFO] Worker exiting (pid: 32585)
[2020-06-21 18:15:19 -0400] [32516] [INFO] Shutting down: Master
[2020-06-21 18:15:19 -0400] [32516] [INFO] Reason: Worker failed to boot.
[2020-06-21 18:15:23 -0400] [521] [INFO] Starting gunicorn 20.0.0
[2020-06-21 18:15:23 -0400] [521] [INFO] Listening at: http://127.0.0.1:10831 (521)
[2020-06-21 18:15:23 -0400] [521] [INFO] Using worker: sync
[2020-06-21 18:15:23 -0400] [582] [INFO] Booting worker with pid: 582
[2020-06-21 18:15:23 -0400] [582] [ERROR] Exception in worker process
Traceback (most recent call last):
  File "/usr/local/lib/python3.5/dist-packages/gunicorn/arbiter.py", line 583, in spawn_worker
    worker.init_process()
  File "/usr/local/lib/python3.5/dist-packages/gunicorn/workers/base.py", line 133, in init_process
    self.load_wsgi()
  File "/usr/local/lib/python3.5/dist-packages/gunicorn/workers/base.py", line 142, in load_wsgi
    self.wsgi = self.app.wsgi()
  File "/usr/local/lib/python3.5/dist-packages/gunicorn/app/base.py", line 67, in wsgi
    self.callable = self.load()
  File "/usr/local/lib/python3.5/dist-packages/gunicorn/app/wsgiapp.py", line 49, in load
    return self.load_wsgiapp()
  File "/usr/local/lib/python3.5/dist-packages/gunicorn/app/wsgiapp.py", line 39, in load_wsgiapp
    return util.import_app(self.app_uri)
  File "/usr/local/lib/python3.5/dist-packages/gunicorn/util.py", line 331, in import_app
    mod = importlib.import_module(module)
  File "/usr/lib/python3.5/importlib/__init__.py", line 126, in import_module
    return _bootstrap._gcd_import(name[level:], package, level)
  File "<frozen importlib._bootstrap>", line 986, in _gcd_import
  File "<frozen importlib._bootstrap>", line 969, in _find_and_load
  File "<frozen importlib._bootstrap>", line 956, in _find_and_load_unlocked
ImportError: No module named 'server'
[2020-06-21 18:15:23 -0400] [582] [INFO] Worker exiting (pid: 582)
[2020-06-21 18:15:23 -0400] [521] [INFO] Shutting down: Master
[2020-06-21 18:15:23 -0400] [521] [INFO] Reason: Worker failed to boot.
[2020-06-21 18:15:28 -0400] [1057] [INFO] Starting gunicorn 20.0.0
[2020-06-21 18:15:28 -0400] [1057] [INFO] Listening at: http://127.0.0.1:10831 (1057)
[2020-06-21 18:15:28 -0400] [1057] [INFO] Using worker: sync
[2020-06-21 18:15:28 -0400] [1105] [INFO] Booting worker with pid: 1105
[2020-06-21 18:15:28 -0400] [1105] [ERROR] Exception in worker process
Traceback (most recent call last):
  File "/usr/local/lib/python3.5/dist-packages/gunicorn/arbiter.py", line 583, in spawn_worker
    worker.init_process()
  File "/usr/local/lib/python3.5/dist-packages/gunicorn/workers/base.py", line 133, in init_process
    self.load_wsgi()
  File "/usr/local/lib/python3.5/dist-packages/gunicorn/workers/base.py", line 142, in load_wsgi
    self.wsgi = self.app.wsgi()
  File "/usr/local/lib/python3.5/dist-packages/gunicorn/app/base.py", line 67, in wsgi
    self.callable = self.load()
  File "/usr/local/lib/python3.5/dist-packages/gunicorn/app/wsgiapp.py", line 49, in load
    return self.load_wsgiapp()
  File "/usr/local/lib/python3.5/dist-packages/gunicorn/app/wsgiapp.py", line 39, in load_wsgiapp
    return util.import_app(self.app_uri)
  File "/usr/local/lib/python3.5/dist-packages/gunicorn/util.py", line 331, in import_app
    mod = importlib.import_module(module)
  File "/usr/lib/python3.5/importlib/__init__.py", line 126, in import_module
    return _bootstrap._gcd_import(name[level:], package, level)
  File "<frozen importlib._bootstrap>", line 986, in _gcd_import
  File "<frozen importlib._bootstrap>", line 969, in _find_and_load
  File "<frozen importlib._bootstrap>", line 956, in _find_and_load_unlocked
ImportError: No module named 'server'
[2020-06-21 18:15:28 -0400] [1105] [INFO] Worker exiting (pid: 1105)
[2020-06-21 18:15:28 -0400] [1057] [INFO] Shutting down: Master
[2020-06-21 18:15:28 -0400] [1057] [INFO] Reason: Worker failed to boot.
/web/activities/mobileapps/run.sh: line 2: venv/bin/activate: No such file or directory
[2020-06-21 18:17:26 -0400] [2927] [INFO] Starting gunicorn 20.0.0
[2020-06-21 18:17:26 -0400] [2927] [INFO] Listening at: http://127.0.0.1:10831 (2927)
[2020-06-21 18:17:26 -0400] [2927] [INFO] Using worker: sync
[2020-06-21 18:17:26 -0400] [2955] [INFO] Booting worker with pid: 2955
[2020-06-21 18:17:26 -0400] [2955] [ERROR] Exception in worker process
Traceback (most recent call last):
  File "/usr/local/lib/python3.5/dist-packages/gunicorn/arbiter.py", line 583, in spawn_worker
    worker.init_process()
  File "/usr/local/lib/python3.5/dist-packages/gunicorn/workers/base.py", line 133, in init_process
    self.load_wsgi()
  File "/usr/local/lib/python3.5/dist-packages/gunicorn/workers/base.py", line 142, in load_wsgi
    self.wsgi = self.app.wsgi()
  File "/usr/local/lib/python3.5/dist-packages/gunicorn/app/base.py", line 67, in wsgi
    self.callable = self.load()
  File "/usr/local/lib/python3.5/dist-packages/gunicorn/app/wsgiapp.py", line 49, in load
    return self.load_wsgiapp()
  File "/usr/local/lib/python3.5/dist-packages/gunicorn/app/wsgiapp.py", line 39, in load_wsgiapp
    return util.import_app(self.app_uri)
  File "/usr/local/lib/python3.5/dist-packages/gunicorn/util.py", line 331, in import_app
    mod = importlib.import_module(module)
  File "/usr/lib/python3.5/importlib/__init__.py", line 126, in import_module
    return _bootstrap._gcd_import(name[level:], package, level)
  File "<frozen importlib._bootstrap>", line 986, in _gcd_import
  File "<frozen importlib._bootstrap>", line 969, in _find_and_load
  File "<frozen importlib._bootstrap>", line 956, in _find_and_load_unlocked
ImportError: No module named 'server'
[2020-06-21 18:17:26 -0400] [2955] [INFO] Worker exiting (pid: 2955)
[2020-06-21 18:17:26 -0400] [2927] [INFO] Shutting down: Master
[2020-06-21 18:17:26 -0400] [2927] [INFO] Reason: Worker failed to boot.
/web/activities/mobileapps/run.sh: line 2: venv/bin/activate: No such file or directory
[2020-06-21 18:17:28 -0400] [2966] [INFO] Starting gunicorn 20.0.0
[2020-06-21 18:17:28 -0400] [2966] [INFO] Listening at: http://127.0.0.1:10831 (2966)
[2020-06-21 18:17:28 -0400] [2966] [INFO] Using worker: sync
[2020-06-21 18:17:28 -0400] [2971] [INFO] Booting worker with pid: 2971
[2020-06-21 18:17:28 -0400] [2971] [ERROR] Exception in worker process
Traceback (most recent call last):
  File "/usr/local/lib/python3.5/dist-packages/gunicorn/arbiter.py", line 583, in spawn_worker
    worker.init_process()
  File "/usr/local/lib/python3.5/dist-packages/gunicorn/workers/base.py", line 133, in init_process
    self.load_wsgi()
  File "/usr/local/lib/python3.5/dist-packages/gunicorn/workers/base.py", line 142, in load_wsgi
    self.wsgi = self.app.wsgi()
  File "/usr/local/lib/python3.5/dist-packages/gunicorn/app/base.py", line 67, in wsgi
    self.callable = self.load()
  File "/usr/local/lib/python3.5/dist-packages/gunicorn/app/wsgiapp.py", line 49, in load
    return self.load_wsgiapp()
  File "/usr/local/lib/python3.5/dist-packages/gunicorn/app/wsgiapp.py", line 39, in load_wsgiapp
    return util.import_app(self.app_uri)
  File "/usr/local/lib/python3.5/dist-packages/gunicorn/util.py", line 331, in import_app
    mod = importlib.import_module(module)
  File "/usr/lib/python3.5/importlib/__init__.py", line 126, in import_module
    return _bootstrap._gcd_import(name[level:], package, level)
  File "<frozen importlib._bootstrap>", line 986, in _gcd_import
  File "<frozen importlib._bootstrap>", line 969, in _find_and_load
  File "<frozen importlib._bootstrap>", line 956, in _find_and_load_unlocked
ImportError: No module named 'server'
[2020-06-21 18:17:28 -0400] [2971] [INFO] Worker exiting (pid: 2971)
[2020-06-21 18:17:28 -0400] [2966] [INFO] Shutting down: Master
[2020-06-21 18:17:28 -0400] [2966] [INFO] Reason: Worker failed to boot.
/web/activities/mobileapps/run.sh: line 2: venv/bin/activate: No such file or directory
[2020-06-21 18:17:32 -0400] [3007] [INFO] Starting gunicorn 20.0.0
[2020-06-21 18:17:32 -0400] [3007] [INFO] Listening at: http://127.0.0.1:10831 (3007)
[2020-06-21 18:17:32 -0400] [3007] [INFO] Using worker: sync
[2020-06-21 18:17:32 -0400] [3013] [INFO] Booting worker with pid: 3013
[2020-06-21 18:17:32 -0400] [3013] [ERROR] Exception in worker process
Traceback (most recent call last):
  File "/usr/local/lib/python3.5/dist-packages/gunicorn/arbiter.py", line 583, in spawn_worker
    worker.init_process()
  File "/usr/local/lib/python3.5/dist-packages/gunicorn/workers/base.py", line 133, in init_process
    self.load_wsgi()
  File "/usr/local/lib/python3.5/dist-packages/gunicorn/workers/base.py", line 142, in load_wsgi
    self.wsgi = self.app.wsgi()
  File "/usr/local/lib/python3.5/dist-packages/gunicorn/app/base.py", line 67, in wsgi
    self.callable = self.load()
  File "/usr/local/lib/python3.5/dist-packages/gunicorn/app/wsgiapp.py", line 49, in load
    return self.load_wsgiapp()
  File "/usr/local/lib/python3.5/dist-packages/gunicorn/app/wsgiapp.py", line 39, in load_wsgiapp
    return util.import_app(self.app_uri)
  File "/usr/local/lib/python3.5/dist-packages/gunicorn/util.py", line 331, in import_app
    mod = importlib.import_module(module)
  File "/usr/lib/python3.5/importlib/__init__.py", line 126, in import_module
    return _bootstrap._gcd_import(name[level:], package, level)
  File "<frozen importlib._bootstrap>", line 986, in _gcd_import
  File "<frozen importlib._bootstrap>", line 969, in _find_and_load
  File "<frozen importlib._bootstrap>", line 956, in _find_and_load_unlocked
ImportError: No module named 'server'
[2020-06-21 18:17:32 -0400] [3013] [INFO] Worker exiting (pid: 3013)
[2020-06-21 18:17:32 -0400] [3007] [INFO] Shutting down: Master
[2020-06-21 18:17:32 -0400] [3007] [INFO] Reason: Worker failed to boot.
/web/activities/mobileapps/run.sh: line 2: venv/bin/activate: No such file or directory
[2020-06-21 18:17:37 -0400] [3043] [INFO] Starting gunicorn 20.0.0
[2020-06-21 18:17:37 -0400] [3043] [INFO] Listening at: http://127.0.0.1:10831 (3043)
[2020-06-21 18:17:37 -0400] [3043] [INFO] Using worker: sync
[2020-06-21 18:17:37 -0400] [3048] [INFO] Booting worker with pid: 3048
[2020-06-21 18:17:37 -0400] [3048] [ERROR] Exception in worker process
Traceback (most recent call last):
  File "/usr/local/lib/python3.5/dist-packages/gunicorn/arbiter.py", line 583, in spawn_worker
    worker.init_process()
  File "/usr/local/lib/python3.5/dist-packages/gunicorn/workers/base.py", line 133, in init_process
    self.load_wsgi()
  File "/usr/local/lib/python3.5/dist-packages/gunicorn/workers/base.py", line 142, in load_wsgi
    self.wsgi = self.app.wsgi()
  File "/usr/local/lib/python3.5/dist-packages/gunicorn/app/base.py", line 67, in wsgi
    self.callable = self.load()
  File "/usr/local/lib/python3.5/dist-packages/gunicorn/app/wsgiapp.py", line 49, in load
    return self.load_wsgiapp()
  File "/usr/local/lib/python3.5/dist-packages/gunicorn/app/wsgiapp.py", line 39, in load_wsgiapp
    return util.import_app(self.app_uri)
  File "/usr/local/lib/python3.5/dist-packages/gunicorn/util.py", line 331, in import_app
    mod = importlib.import_module(module)
  File "/usr/lib/python3.5/importlib/__init__.py", line 126, in import_module
    return _bootstrap._gcd_import(name[level:], package, level)
  File "<frozen importlib._bootstrap>", line 986, in _gcd_import
  File "<frozen importlib._bootstrap>", line 969, in _find_and_load
  File "<frozen importlib._bootstrap>", line 956, in _find_and_load_unlocked
ImportError: No module named 'server'
[2020-06-21 18:17:37 -0400] [3048] [INFO] Worker exiting (pid: 3048)
[2020-06-21 18:17:37 -0400] [3043] [INFO] Shutting down: Master
[2020-06-21 18:17:37 -0400] [3043] [INFO] Reason: Worker failed to boot.
supervisor: couldn't chdir to /web/activities/mobileapps/public: ENOENT
supervisor: child process was not spawned
supervisor: couldn't chdir to /web/activities/mobileapps/public: ENOENT
supervisor: child process was not spawned
supervisor: couldn't chdir to /web/activities/mobileapps/public: ENOENT
supervisor: child process was not spawned
supervisor: couldn't chdir to /web/activities/mobileapps/public: ENOENT
supervisor: child process was not spawned
/web/activities/mobileapps/run.sh: line 2: ../mobileapps/venv/bin/activate: No such file or directory
[2020-06-21 18:24:20 -0400] [8046] [INFO] Starting gunicorn 20.0.0
[2020-06-21 18:24:20 -0400] [8046] [INFO] Listening at: http://127.0.0.1:10831 (8046)
[2020-06-21 18:24:20 -0400] [8046] [INFO] Using worker: sync
[2020-06-21 18:24:20 -0400] [8051] [INFO] Booting worker with pid: 8051
[2020-06-21 18:24:20 -0400] [8051] [ERROR] Exception in worker process
Traceback (most recent call last):
  File "/usr/local/lib/python3.5/dist-packages/gunicorn/arbiter.py", line 583, in spawn_worker
    worker.init_process()
  File "/usr/local/lib/python3.5/dist-packages/gunicorn/workers/base.py", line 133, in init_process
    self.load_wsgi()
  File "/usr/local/lib/python3.5/dist-packages/gunicorn/workers/base.py", line 142, in load_wsgi
    self.wsgi = self.app.wsgi()
  File "/usr/local/lib/python3.5/dist-packages/gunicorn/app/base.py", line 67, in wsgi
    self.callable = self.load()
  File "/usr/local/lib/python3.5/dist-packages/gunicorn/app/wsgiapp.py", line 49, in load
    return self.load_wsgiapp()
  File "/usr/local/lib/python3.5/dist-packages/gunicorn/app/wsgiapp.py", line 39, in load_wsgiapp
    return util.import_app(self.app_uri)
  File "/usr/local/lib/python3.5/dist-packages/gunicorn/util.py", line 331, in import_app
    mod = importlib.import_module(module)
  File "/usr/lib/python3.5/importlib/__init__.py", line 126, in import_module
    return _bootstrap._gcd_import(name[level:], package, level)
  File "<frozen importlib._bootstrap>", line 986, in _gcd_import
  File "<frozen importlib._bootstrap>", line 969, in _find_and_load
  File "<frozen importlib._bootstrap>", line 956, in _find_and_load_unlocked
ImportError: No module named 'server'
[2020-06-21 18:24:20 -0400] [8051] [INFO] Worker exiting (pid: 8051)
[2020-06-21 18:24:20 -0400] [8046] [INFO] Shutting down: Master
[2020-06-21 18:24:20 -0400] [8046] [INFO] Reason: Worker failed to boot.
/web/activities/mobileapps/run.sh: line 2: ../mobileapps/venv/bin/activate: No such file or directory
[2020-06-21 18:24:22 -0400] [8084] [INFO] Starting gunicorn 20.0.0
[2020-06-21 18:24:22 -0400] [8084] [INFO] Listening at: http://127.0.0.1:10831 (8084)
[2020-06-21 18:24:22 -0400] [8084] [INFO] Using worker: sync
[2020-06-21 18:24:22 -0400] [8093] [INFO] Booting worker with pid: 8093
[2020-06-21 18:24:22 -0400] [8093] [ERROR] Exception in worker process
Traceback (most recent call last):
  File "/usr/local/lib/python3.5/dist-packages/gunicorn/arbiter.py", line 583, in spawn_worker
    worker.init_process()
  File "/usr/local/lib/python3.5/dist-packages/gunicorn/workers/base.py", line 133, in init_process
    self.load_wsgi()
  File "/usr/local/lib/python3.5/dist-packages/gunicorn/workers/base.py", line 142, in load_wsgi
    self.wsgi = self.app.wsgi()
  File "/usr/local/lib/python3.5/dist-packages/gunicorn/app/base.py", line 67, in wsgi
    self.callable = self.load()
  File "/usr/local/lib/python3.5/dist-packages/gunicorn/app/wsgiapp.py", line 49, in load
    return self.load_wsgiapp()
  File "/usr/local/lib/python3.5/dist-packages/gunicorn/app/wsgiapp.py", line 39, in load_wsgiapp
    return util.import_app(self.app_uri)
  File "/usr/local/lib/python3.5/dist-packages/gunicorn/util.py", line 331, in import_app
    mod = importlib.import_module(module)
  File "/usr/lib/python3.5/importlib/__init__.py", line 126, in import_module
    return _bootstrap._gcd_import(name[level:], package, level)
  File "<frozen importlib._bootstrap>", line 986, in _gcd_import
  File "<frozen importlib._bootstrap>", line 969, in _find_and_load
  File "<frozen importlib._bootstrap>", line 956, in _find_and_load_unlocked
ImportError: No module named 'server'
[2020-06-21 18:24:22 -0400] [8093] [INFO] Worker exiting (pid: 8093)
[2020-06-21 18:24:22 -0400] [8084] [INFO] Shutting down: Master
[2020-06-21 18:24:22 -0400] [8084] [INFO] Reason: Worker failed to boot.
/web/activities/mobileapps/run.sh: line 2: ../mobileapps/venv/bin/activate: No such file or directory
[2020-06-21 18:24:26 -0400] [8127] [INFO] Starting gunicorn 20.0.0
[2020-06-21 18:24:26 -0400] [8127] [INFO] Listening at: http://127.0.0.1:10831 (8127)
[2020-06-21 18:24:26 -0400] [8127] [INFO] Using worker: sync
[2020-06-21 18:24:26 -0400] [8137] [INFO] Booting worker with pid: 8137
[2020-06-21 18:24:26 -0400] [8137] [ERROR] Exception in worker process
Traceback (most recent call last):
  File "/usr/local/lib/python3.5/dist-packages/gunicorn/arbiter.py", line 583, in spawn_worker
    worker.init_process()
  File "/usr/local/lib/python3.5/dist-packages/gunicorn/workers/base.py", line 133, in init_process
    self.load_wsgi()
  File "/usr/local/lib/python3.5/dist-packages/gunicorn/workers/base.py", line 142, in load_wsgi
    self.wsgi = self.app.wsgi()
  File "/usr/local/lib/python3.5/dist-packages/gunicorn/app/base.py", line 67, in wsgi
    self.callable = self.load()
  File "/usr/local/lib/python3.5/dist-packages/gunicorn/app/wsgiapp.py", line 49, in load
    return self.load_wsgiapp()
  File "/usr/local/lib/python3.5/dist-packages/gunicorn/app/wsgiapp.py", line 39, in load_wsgiapp
    return util.import_app(self.app_uri)
  File "/usr/local/lib/python3.5/dist-packages/gunicorn/util.py", line 331, in import_app
    mod = importlib.import_module(module)
  File "/usr/lib/python3.5/importlib/__init__.py", line 126, in import_module
    return _bootstrap._gcd_import(name[level:], package, level)
  File "<frozen importlib._bootstrap>", line 986, in _gcd_import
  File "<frozen importlib._bootstrap>", line 969, in _find_and_load
  File "<frozen importlib._bootstrap>", line 956, in _find_and_load_unlocked
ImportError: No module named 'server'
[2020-06-21 18:24:26 -0400] [8137] [INFO] Worker exiting (pid: 8137)
[2020-06-21 18:24:26 -0400] [8127] [INFO] Shutting down: Master
[2020-06-21 18:24:26 -0400] [8127] [INFO] Reason: Worker failed to boot.
/web/activities/mobileapps/run.sh: line 2: ../mobileapps/venv/bin/activate: No such file or directory
[2020-06-21 18:24:31 -0400] [8169] [INFO] Starting gunicorn 20.0.0
[2020-06-21 18:24:31 -0400] [8169] [INFO] Listening at: http://127.0.0.1:10831 (8169)
[2020-06-21 18:24:31 -0400] [8169] [INFO] Using worker: sync
[2020-06-21 18:24:31 -0400] [8173] [INFO] Booting worker with pid: 8173
[2020-06-21 18:24:31 -0400] [8173] [ERROR] Exception in worker process
Traceback (most recent call last):
  File "/usr/local/lib/python3.5/dist-packages/gunicorn/arbiter.py", line 583, in spawn_worker
    worker.init_process()
  File "/usr/local/lib/python3.5/dist-packages/gunicorn/workers/base.py", line 133, in init_process
    self.load_wsgi()
  File "/usr/local/lib/python3.5/dist-packages/gunicorn/workers/base.py", line 142, in load_wsgi
    self.wsgi = self.app.wsgi()
  File "/usr/local/lib/python3.5/dist-packages/gunicorn/app/base.py", line 67, in wsgi
    self.callable = self.load()
  File "/usr/local/lib/python3.5/dist-packages/gunicorn/app/wsgiapp.py", line 49, in load
    return self.load_wsgiapp()
  File "/usr/local/lib/python3.5/dist-packages/gunicorn/app/wsgiapp.py", line 39, in load_wsgiapp
    return util.import_app(self.app_uri)
  File "/usr/local/lib/python3.5/dist-packages/gunicorn/util.py", line 331, in import_app
    mod = importlib.import_module(module)
  File "/usr/lib/python3.5/importlib/__init__.py", line 126, in import_module
    return _bootstrap._gcd_import(name[level:], package, level)
  File "<frozen importlib._bootstrap>", line 986, in _gcd_import
  File "<frozen importlib._bootstrap>", line 969, in _find_and_load
  File "<frozen importlib._bootstrap>", line 956, in _find_and_load_unlocked
ImportError: No module named 'server'
[2020-06-21 18:24:31 -0400] [8173] [INFO] Worker exiting (pid: 8173)
[2020-06-21 18:24:31 -0400] [8169] [INFO] Shutting down: Master
[2020-06-21 18:24:31 -0400] [8169] [INFO] Reason: Worker failed to boot.
/web/activities/mobileapps/run.sh: line 2: ../mobileapps/venv/bin/activate: No such file or directory
[2020-06-21 18:27:08 -0400] [11332] [INFO] Starting gunicorn 20.0.0
[2020-06-21 18:27:08 -0400] [11332] [INFO] Listening at: http://127.0.0.1:10831 (11332)
[2020-06-21 18:27:08 -0400] [11332] [INFO] Using worker: sync
[2020-06-21 18:27:08 -0400] [11336] [INFO] Booting worker with pid: 11336
[2020-06-21 18:27:08 -0400] [11336] [ERROR] Exception in worker process
Traceback (most recent call last):
  File "/usr/local/lib/python3.5/dist-packages/gunicorn/arbiter.py", line 583, in spawn_worker
    worker.init_process()
  File "/usr/local/lib/python3.5/dist-packages/gunicorn/workers/base.py", line 133, in init_process
    self.load_wsgi()
  File "/usr/local/lib/python3.5/dist-packages/gunicorn/workers/base.py", line 142, in load_wsgi
    self.wsgi = self.app.wsgi()
  File "/usr/local/lib/python3.5/dist-packages/gunicorn/app/base.py", line 67, in wsgi
    self.callable = self.load()
  File "/usr/local/lib/python3.5/dist-packages/gunicorn/app/wsgiapp.py", line 49, in load
    return self.load_wsgiapp()
  File "/usr/local/lib/python3.5/dist-packages/gunicorn/app/wsgiapp.py", line 39, in load_wsgiapp
    return util.import_app(self.app_uri)
  File "/usr/local/lib/python3.5/dist-packages/gunicorn/util.py", line 331, in import_app
    mod = importlib.import_module(module)
  File "/usr/lib/python3.5/importlib/__init__.py", line 126, in import_module
    return _bootstrap._gcd_import(name[level:], package, level)
  File "<frozen importlib._bootstrap>", line 986, in _gcd_import
  File "<frozen importlib._bootstrap>", line 969, in _find_and_load
  File "<frozen importlib._bootstrap>", line 956, in _find_and_load_unlocked
ImportError: No module named 'server'
[2020-06-21 18:27:08 -0400] [11336] [INFO] Worker exiting (pid: 11336)
[2020-06-21 18:27:08 -0400] [11332] [INFO] Shutting down: Master
[2020-06-21 18:27:08 -0400] [11332] [INFO] Reason: Worker failed to boot.
/web/activities/mobileapps/run.sh: line 2: ../mobileapps/venv/bin/activate: No such file or directory
[2020-06-21 18:27:11 -0400] [11349] [INFO] Starting gunicorn 20.0.0
[2020-06-21 18:27:11 -0400] [11349] [INFO] Listening at: http://127.0.0.1:10831 (11349)
[2020-06-21 18:27:11 -0400] [11349] [INFO] Using worker: sync
[2020-06-21 18:27:11 -0400] [11358] [INFO] Booting worker with pid: 11358
[2020-06-21 18:27:11 -0400] [11358] [ERROR] Exception in worker process
Traceback (most recent call last):
  File "/usr/local/lib/python3.5/dist-packages/gunicorn/arbiter.py", line 583, in spawn_worker
    worker.init_process()
  File "/usr/local/lib/python3.5/dist-packages/gunicorn/workers/base.py", line 133, in init_process
    self.load_wsgi()
  File "/usr/local/lib/python3.5/dist-packages/gunicorn/workers/base.py", line 142, in load_wsgi
    self.wsgi = self.app.wsgi()
  File "/usr/local/lib/python3.5/dist-packages/gunicorn/app/base.py", line 67, in wsgi
    self.callable = self.load()
  File "/usr/local/lib/python3.5/dist-packages/gunicorn/app/wsgiapp.py", line 49, in load
    return self.load_wsgiapp()
  File "/usr/local/lib/python3.5/dist-packages/gunicorn/app/wsgiapp.py", line 39, in load_wsgiapp
    return util.import_app(self.app_uri)
  File "/usr/local/lib/python3.5/dist-packages/gunicorn/util.py", line 331, in import_app
    mod = importlib.import_module(module)
  File "/usr/lib/python3.5/importlib/__init__.py", line 126, in import_module
    return _bootstrap._gcd_import(name[level:], package, level)
  File "<frozen importlib._bootstrap>", line 986, in _gcd_import
  File "<frozen importlib._bootstrap>", line 969, in _find_and_load
  File "<frozen importlib._bootstrap>", line 956, in _find_and_load_unlocked
ImportError: No module named 'server'
[2020-06-21 18:27:11 -0400] [11358] [INFO] Worker exiting (pid: 11358)
[2020-06-21 18:27:11 -0400] [11349] [INFO] Shutting down: Master
[2020-06-21 18:27:11 -0400] [11349] [INFO] Reason: Worker failed to boot.
/web/activities/mobileapps/run.sh: line 2: ../mobileapps/venv/bin/activate: No such file or directory
[2020-06-21 18:27:15 -0400] [11380] [INFO] Starting gunicorn 20.0.0
[2020-06-21 18:27:15 -0400] [11380] [INFO] Listening at: http://127.0.0.1:10831 (11380)
[2020-06-21 18:27:15 -0400] [11380] [INFO] Using worker: sync
[2020-06-21 18:27:15 -0400] [11390] [INFO] Booting worker with pid: 11390
[2020-06-21 18:27:15 -0400] [11390] [ERROR] Exception in worker process
Traceback (most recent call last):
  File "/usr/local/lib/python3.5/dist-packages/gunicorn/arbiter.py", line 583, in spawn_worker
    worker.init_process()
  File "/usr/local/lib/python3.5/dist-packages/gunicorn/workers/base.py", line 133, in init_process
    self.load_wsgi()
  File "/usr/local/lib/python3.5/dist-packages/gunicorn/workers/base.py", line 142, in load_wsgi
    self.wsgi = self.app.wsgi()
  File "/usr/local/lib/python3.5/dist-packages/gunicorn/app/base.py", line 67, in wsgi
    self.callable = self.load()
  File "/usr/local/lib/python3.5/dist-packages/gunicorn/app/wsgiapp.py", line 49, in load
    return self.load_wsgiapp()
  File "/usr/local/lib/python3.5/dist-packages/gunicorn/app/wsgiapp.py", line 39, in load_wsgiapp
    return util.import_app(self.app_uri)
  File "/usr/local/lib/python3.5/dist-packages/gunicorn/util.py", line 331, in import_app
    mod = importlib.import_module(module)
  File "/usr/lib/python3.5/importlib/__init__.py", line 126, in import_module
    return _bootstrap._gcd_import(name[level:], package, level)
  File "<frozen importlib._bootstrap>", line 986, in _gcd_import
  File "<frozen importlib._bootstrap>", line 969, in _find_and_load
  File "<frozen importlib._bootstrap>", line 956, in _find_and_load_unlocked
ImportError: No module named 'server'
[2020-06-21 18:27:15 -0400] [11390] [INFO] Worker exiting (pid: 11390)
[2020-06-21 18:27:15 -0400] [11380] [INFO] Shutting down: Master
[2020-06-21 18:27:15 -0400] [11380] [INFO] Reason: Worker failed to boot.
/web/activities/mobileapps/run.sh: line 2: ../mobileapps/venv/bin/activate: No such file or directory
[2020-06-21 18:27:19 -0400] [11421] [INFO] Starting gunicorn 20.0.0
[2020-06-21 18:27:19 -0400] [11421] [INFO] Listening at: http://127.0.0.1:10831 (11421)
[2020-06-21 18:27:19 -0400] [11421] [INFO] Using worker: sync
[2020-06-21 18:27:19 -0400] [11434] [INFO] Booting worker with pid: 11434
[2020-06-21 18:27:19 -0400] [11434] [ERROR] Exception in worker process
Traceback (most recent call last):
  File "/usr/local/lib/python3.5/dist-packages/gunicorn/arbiter.py", line 583, in spawn_worker
    worker.init_process()
  File "/usr/local/lib/python3.5/dist-packages/gunicorn/workers/base.py", line 133, in init_process
    self.load_wsgi()
  File "/usr/local/lib/python3.5/dist-packages/gunicorn/workers/base.py", line 142, in load_wsgi
    self.wsgi = self.app.wsgi()
  File "/usr/local/lib/python3.5/dist-packages/gunicorn/app/base.py", line 67, in wsgi
    self.callable = self.load()
  File "/usr/local/lib/python3.5/dist-packages/gunicorn/app/wsgiapp.py", line 49, in load
    return self.load_wsgiapp()
  File "/usr/local/lib/python3.5/dist-packages/gunicorn/app/wsgiapp.py", line 39, in load_wsgiapp
    return util.import_app(self.app_uri)
  File "/usr/local/lib/python3.5/dist-packages/gunicorn/util.py", line 331, in import_app
    mod = importlib.import_module(module)
  File "/usr/lib/python3.5/importlib/__init__.py", line 126, in import_module
    return _bootstrap._gcd_import(name[level:], package, level)
  File "<frozen importlib._bootstrap>", line 986, in _gcd_import
  File "<frozen importlib._bootstrap>", line 969, in _find_and_load
  File "<frozen importlib._bootstrap>", line 956, in _find_and_load_unlocked
ImportError: No module named 'server'
[2020-06-21 18:27:19 -0400] [11434] [INFO] Worker exiting (pid: 11434)
[2020-06-21 18:27:19 -0400] [11421] [INFO] Shutting down: Master
[2020-06-21 18:27:19 -0400] [11421] [INFO] Reason: Worker failed to boot.
/web/activities/mobileapps/run.sh: line 2: ../mobileapps/venv/bin/activate: No such file or directory
[2020-06-21 18:28:38 -0400] [12167] [INFO] Starting gunicorn 20.0.0
[2020-06-21 18:28:38 -0400] [12167] [INFO] Listening at: http://127.0.0.1:10831 (12167)
[2020-06-21 18:28:38 -0400] [12167] [INFO] Using worker: sync
[2020-06-21 18:28:38 -0400] [12217] [INFO] Booting worker with pid: 12217
[2020-06-21 18:28:38 -0400] [12217] [ERROR] Exception in worker process
Traceback (most recent call last):
  File "/usr/local/lib/python3.5/dist-packages/gunicorn/arbiter.py", line 583, in spawn_worker
    worker.init_process()
  File "/usr/local/lib/python3.5/dist-packages/gunicorn/workers/base.py", line 133, in init_process
    self.load_wsgi()
  File "/usr/local/lib/python3.5/dist-packages/gunicorn/workers/base.py", line 142, in load_wsgi
    self.wsgi = self.app.wsgi()
  File "/usr/local/lib/python3.5/dist-packages/gunicorn/app/base.py", line 67, in wsgi
    self.callable = self.load()
  File "/usr/local/lib/python3.5/dist-packages/gunicorn/app/wsgiapp.py", line 49, in load
    return self.load_wsgiapp()
  File "/usr/local/lib/python3.5/dist-packages/gunicorn/app/wsgiapp.py", line 39, in load_wsgiapp
    return util.import_app(self.app_uri)
  File "/usr/local/lib/python3.5/dist-packages/gunicorn/util.py", line 331, in import_app
    mod = importlib.import_module(module)
  File "/usr/lib/python3.5/importlib/__init__.py", line 126, in import_module
    return _bootstrap._gcd_import(name[level:], package, level)
  File "<frozen importlib._bootstrap>", line 986, in _gcd_import
  File "<frozen importlib._bootstrap>", line 969, in _find_and_load
  File "<frozen importlib._bootstrap>", line 956, in _find_and_load_unlocked
ImportError: No module named 'server'
[2020-06-21 18:28:38 -0400] [12217] [INFO] Worker exiting (pid: 12217)
[2020-06-21 18:28:38 -0400] [12167] [INFO] Shutting down: Master
[2020-06-21 18:28:38 -0400] [12167] [INFO] Reason: Worker failed to boot.
/web/activities/mobileapps/run.sh: line 2: ../mobileapps/venv/bin/activate: No such file or directory
[2020-06-21 18:28:41 -0400] [12229] [INFO] Starting gunicorn 20.0.0
[2020-06-21 18:28:41 -0400] [12229] [INFO] Listening at: http://127.0.0.1:10831 (12229)
[2020-06-21 18:28:41 -0400] [12229] [INFO] Using worker: sync
[2020-06-21 18:28:41 -0400] [12234] [INFO] Booting worker with pid: 12234
[2020-06-21 18:28:41 -0400] [12234] [ERROR] Exception in worker process
Traceback (most recent call last):
  File "/usr/local/lib/python3.5/dist-packages/gunicorn/arbiter.py", line 583, in spawn_worker
    worker.init_process()
  File "/usr/local/lib/python3.5/dist-packages/gunicorn/workers/base.py", line 133, in init_process
    self.load_wsgi()
  File "/usr/local/lib/python3.5/dist-packages/gunicorn/workers/base.py", line 142, in load_wsgi
    self.wsgi = self.app.wsgi()
  File "/usr/local/lib/python3.5/dist-packages/gunicorn/app/base.py", line 67, in wsgi
    self.callable = self.load()
  File "/usr/local/lib/python3.5/dist-packages/gunicorn/app/wsgiapp.py", line 49, in load
    return self.load_wsgiapp()
  File "/usr/local/lib/python3.5/dist-packages/gunicorn/app/wsgiapp.py", line 39, in load_wsgiapp
    return util.import_app(self.app_uri)
  File "/usr/local/lib/python3.5/dist-packages/gunicorn/util.py", line 331, in import_app
    mod = importlib.import_module(module)
  File "/usr/lib/python3.5/importlib/__init__.py", line 126, in import_module
    return _bootstrap._gcd_import(name[level:], package, level)
  File "<frozen importlib._bootstrap>", line 986, in _gcd_import
  File "<frozen importlib._bootstrap>", line 969, in _find_and_load
  File "<frozen importlib._bootstrap>", line 956, in _find_and_load_unlocked
ImportError: No module named 'server'
[2020-06-21 18:28:41 -0400] [12234] [INFO] Worker exiting (pid: 12234)
[2020-06-21 18:28:41 -0400] [12229] [INFO] Shutting down: Master
[2020-06-21 18:28:41 -0400] [12229] [INFO] Reason: Worker failed to boot.
/web/activities/mobileapps/run.sh: line 2: ../mobileapps/venv/bin/activate: No such file or directory
[2020-06-21 18:28:44 -0400] [12265] [INFO] Starting gunicorn 20.0.0
[2020-06-21 18:28:44 -0400] [12265] [INFO] Listening at: http://127.0.0.1:10831 (12265)
[2020-06-21 18:28:44 -0400] [12265] [INFO] Using worker: sync
[2020-06-21 18:28:44 -0400] [12280] [INFO] Booting worker with pid: 12280
[2020-06-21 18:28:44 -0400] [12280] [ERROR] Exception in worker process
Traceback (most recent call last):
  File "/usr/local/lib/python3.5/dist-packages/gunicorn/arbiter.py", line 583, in spawn_worker
    worker.init_process()
  File "/usr/local/lib/python3.5/dist-packages/gunicorn/workers/base.py", line 133, in init_process
    self.load_wsgi()
  File "/usr/local/lib/python3.5/dist-packages/gunicorn/workers/base.py", line 142, in load_wsgi
    self.wsgi = self.app.wsgi()
  File "/usr/local/lib/python3.5/dist-packages/gunicorn/app/base.py", line 67, in wsgi
    self.callable = self.load()
  File "/usr/local/lib/python3.5/dist-packages/gunicorn/app/wsgiapp.py", line 49, in load
    return self.load_wsgiapp()
  File "/usr/local/lib/python3.5/dist-packages/gunicorn/app/wsgiapp.py", line 39, in load_wsgiapp
    return util.import_app(self.app_uri)
  File "/usr/local/lib/python3.5/dist-packages/gunicorn/util.py", line 331, in import_app
    mod = importlib.import_module(module)
  File "/usr/lib/python3.5/importlib/__init__.py", line 126, in import_module
    return _bootstrap._gcd_import(name[level:], package, level)
  File "<frozen importlib._bootstrap>", line 986, in _gcd_import
  File "<frozen importlib._bootstrap>", line 969, in _find_and_load
  File "<frozen importlib._bootstrap>", line 956, in _find_and_load_unlocked
ImportError: No module named 'server'
[2020-06-21 18:28:44 -0400] [12280] [INFO] Worker exiting (pid: 12280)
[2020-06-21 18:28:45 -0400] [12265] [INFO] Shutting down: Master
[2020-06-21 18:28:45 -0400] [12265] [INFO] Reason: Worker failed to boot.
/web/activities/mobileapps/run.sh: line 2: ../mobileapps/venv/bin/activate: No such file or directory
[2020-06-21 18:28:46 -0400] [12289] [INFO] Starting gunicorn 20.0.0
[2020-06-21 18:28:46 -0400] [12289] [INFO] Listening at: http://127.0.0.1:10831 (12289)
[2020-06-21 18:28:46 -0400] [12289] [INFO] Using worker: sync
[2020-06-21 18:28:46 -0400] [12317] [INFO] Booting worker with pid: 12317
[2020-06-21 18:28:46 -0400] [12317] [ERROR] Exception in worker process
Traceback (most recent call last):
  File "/usr/local/lib/python3.5/dist-packages/gunicorn/arbiter.py", line 583, in spawn_worker
    worker.init_process()
  File "/usr/local/lib/python3.5/dist-packages/gunicorn/workers/base.py", line 133, in init_process
    self.load_wsgi()
  File "/usr/local/lib/python3.5/dist-packages/gunicorn/workers/base.py", line 142, in load_wsgi
    self.wsgi = self.app.wsgi()
  File "/usr/local/lib/python3.5/dist-packages/gunicorn/app/base.py", line 67, in wsgi
    self.callable = self.load()
  File "/usr/local/lib/python3.5/dist-packages/gunicorn/app/wsgiapp.py", line 49, in load
    return self.load_wsgiapp()
  File "/usr/local/lib/python3.5/dist-packages/gunicorn/app/wsgiapp.py", line 39, in load_wsgiapp
    return util.import_app(self.app_uri)
  File "/usr/local/lib/python3.5/dist-packages/gunicorn/util.py", line 331, in import_app
    mod = importlib.import_module(module)
  File "/usr/lib/python3.5/importlib/__init__.py", line 126, in import_module
    return _bootstrap._gcd_import(name[level:], package, level)
  File "<frozen importlib._bootstrap>", line 986, in _gcd_import
  File "<frozen importlib._bootstrap>", line 969, in _find_and_load
  File "<frozen importlib._bootstrap>", line 956, in _find_and_load_unlocked
ImportError: No module named 'server'
[2020-06-21 18:28:46 -0400] [12317] [INFO] Worker exiting (pid: 12317)
[2020-06-21 18:28:46 -0400] [12289] [INFO] Shutting down: Master
[2020-06-21 18:28:46 -0400] [12289] [INFO] Reason: Worker failed to boot.
/web/activities/mobileapps/run.sh: line 2: ../mobileapps/venv/bin/activate: No such file or directory
[2020-06-21 18:28:51 -0400] [12361] [INFO] Starting gunicorn 20.0.0
[2020-06-21 18:28:51 -0400] [12361] [INFO] Listening at: http://127.0.0.1:10831 (12361)
[2020-06-21 18:28:51 -0400] [12361] [INFO] Using worker: sync
[2020-06-21 18:28:51 -0400] [12367] [INFO] Booting worker with pid: 12367
[2020-06-21 18:28:51 -0400] [12367] [ERROR] Exception in worker process
Traceback (most recent call last):
  File "/usr/local/lib/python3.5/dist-packages/gunicorn/arbiter.py", line 583, in spawn_worker
    worker.init_process()
  File "/usr/local/lib/python3.5/dist-packages/gunicorn/workers/base.py", line 133, in init_process
    self.load_wsgi()
  File "/usr/local/lib/python3.5/dist-packages/gunicorn/workers/base.py", line 142, in load_wsgi
    self.wsgi = self.app.wsgi()
  File "/usr/local/lib/python3.5/dist-packages/gunicorn/app/base.py", line 67, in wsgi
    self.callable = self.load()
  File "/usr/local/lib/python3.5/dist-packages/gunicorn/app/wsgiapp.py", line 49, in load
    return self.load_wsgiapp()
  File "/usr/local/lib/python3.5/dist-packages/gunicorn/app/wsgiapp.py", line 39, in load_wsgiapp
    return util.import_app(self.app_uri)
  File "/usr/local/lib/python3.5/dist-packages/gunicorn/util.py", line 331, in import_app
    mod = importlib.import_module(module)
  File "/usr/lib/python3.5/importlib/__init__.py", line 126, in import_module
    return _bootstrap._gcd_import(name[level:], package, level)
  File "<frozen importlib._bootstrap>", line 986, in _gcd_import
  File "<frozen importlib._bootstrap>", line 969, in _find_and_load
  File "<frozen importlib._bootstrap>", line 956, in _find_and_load_unlocked
ImportError: No module named 'server'
[2020-06-21 18:28:51 -0400] [12367] [INFO] Worker exiting (pid: 12367)
[2020-06-21 18:28:51 -0400] [12361] [INFO] Shutting down: Master
[2020-06-21 18:28:51 -0400] [12361] [INFO] Reason: Worker failed to boot.
/web/activities/mobileapps/run.sh: line 2: ../mobileapps/venv/bin/activate: No such file or directory
[2020-06-21 18:31:49 -0400] [15468] [INFO] Starting gunicorn 20.0.0
[2020-06-21 18:31:49 -0400] [15468] [INFO] Listening at: http://127.0.0.1:10831 (15468)
[2020-06-21 18:31:49 -0400] [15468] [INFO] Using worker: sync
[2020-06-21 18:31:49 -0400] [15474] [INFO] Booting worker with pid: 15474
[2020-06-21 18:31:49 -0400] [15474] [ERROR] Exception in worker process
Traceback (most recent call last):
  File "/usr/local/lib/python3.5/dist-packages/gunicorn/arbiter.py", line 583, in spawn_worker
    worker.init_process()
  File "/usr/local/lib/python3.5/dist-packages/gunicorn/workers/base.py", line 133, in init_process
    self.load_wsgi()
  File "/usr/local/lib/python3.5/dist-packages/gunicorn/workers/base.py", line 142, in load_wsgi
    self.wsgi = self.app.wsgi()
  File "/usr/local/lib/python3.5/dist-packages/gunicorn/app/base.py", line 67, in wsgi
    self.callable = self.load()
  File "/usr/local/lib/python3.5/dist-packages/gunicorn/app/wsgiapp.py", line 49, in load
    return self.load_wsgiapp()
  File "/usr/local/lib/python3.5/dist-packages/gunicorn/app/wsgiapp.py", line 39, in load_wsgiapp
    return util.import_app(self.app_uri)
  File "/usr/local/lib/python3.5/dist-packages/gunicorn/util.py", line 331, in import_app
    mod = importlib.import_module(module)
  File "/usr/lib/python3.5/importlib/__init__.py", line 126, in import_module
    return _bootstrap._gcd_import(name[level:], package, level)
  File "<frozen importlib._bootstrap>", line 986, in _gcd_import
  File "<frozen importlib._bootstrap>", line 969, in _find_and_load
  File "<frozen importlib._bootstrap>", line 956, in _find_and_load_unlocked
ImportError: No module named 'server'
[2020-06-21 18:31:49 -0400] [15474] [INFO] Worker exiting (pid: 15474)
[2020-06-21 18:31:49 -0400] [15468] [INFO] Shutting down: Master
[2020-06-21 18:31:49 -0400] [15468] [INFO] Reason: Worker failed to boot.
/web/activities/mobileapps/run.sh: line 2: ../mobileapps/venv/bin/activate: No such file or directory
[2020-06-21 18:31:51 -0400] [15516] [INFO] Starting gunicorn 20.0.0
[2020-06-21 18:31:51 -0400] [15516] [INFO] Listening at: http://127.0.0.1:10831 (15516)
[2020-06-21 18:31:51 -0400] [15516] [INFO] Using worker: sync
[2020-06-21 18:31:51 -0400] [15526] [INFO] Booting worker with pid: 15526
[2020-06-21 18:31:51 -0400] [15526] [ERROR] Exception in worker process
Traceback (most recent call last):
  File "/usr/local/lib/python3.5/dist-packages/gunicorn/arbiter.py", line 583, in spawn_worker
    worker.init_process()
  File "/usr/local/lib/python3.5/dist-packages/gunicorn/workers/base.py", line 133, in init_process
    self.load_wsgi()
  File "/usr/local/lib/python3.5/dist-packages/gunicorn/workers/base.py", line 142, in load_wsgi
    self.wsgi = self.app.wsgi()
  File "/usr/local/lib/python3.5/dist-packages/gunicorn/app/base.py", line 67, in wsgi
    self.callable = self.load()
  File "/usr/local/lib/python3.5/dist-packages/gunicorn/app/wsgiapp.py", line 49, in load
    return self.load_wsgiapp()
  File "/usr/local/lib/python3.5/dist-packages/gunicorn/app/wsgiapp.py", line 39, in load_wsgiapp
    return util.import_app(self.app_uri)
  File "/usr/local/lib/python3.5/dist-packages/gunicorn/util.py", line 331, in import_app
    mod = importlib.import_module(module)
  File "/usr/lib/python3.5/importlib/__init__.py", line 126, in import_module
    return _bootstrap._gcd_import(name[level:], package, level)
  File "<frozen importlib._bootstrap>", line 986, in _gcd_import
  File "<frozen importlib._bootstrap>", line 969, in _find_and_load
  File "<frozen importlib._bootstrap>", line 956, in _find_and_load_unlocked
ImportError: No module named 'server'
[2020-06-21 18:31:51 -0400] [15526] [INFO] Worker exiting (pid: 15526)
[2020-06-21 18:31:52 -0400] [15516] [INFO] Shutting down: Master
[2020-06-21 18:31:52 -0400] [15516] [INFO] Reason: Worker failed to boot.
/web/activities/mobileapps/run.sh: line 2: ../mobileapps/venv/bin/activate: No such file or directory
[2020-06-21 18:31:55 -0400] [15572] [INFO] Starting gunicorn 20.0.0
[2020-06-21 18:31:55 -0400] [15572] [INFO] Listening at: http://127.0.0.1:10831 (15572)
[2020-06-21 18:31:55 -0400] [15572] [INFO] Using worker: sync
[2020-06-21 18:31:55 -0400] [15579] [INFO] Booting worker with pid: 15579
[2020-06-21 18:31:55 -0400] [15579] [ERROR] Exception in worker process
Traceback (most recent call last):
  File "/usr/local/lib/python3.5/dist-packages/gunicorn/arbiter.py", line 583, in spawn_worker
    worker.init_process()
  File "/usr/local/lib/python3.5/dist-packages/gunicorn/workers/base.py", line 133, in init_process
    self.load_wsgi()
  File "/usr/local/lib/python3.5/dist-packages/gunicorn/workers/base.py", line 142, in load_wsgi
    self.wsgi = self.app.wsgi()
  File "/usr/local/lib/python3.5/dist-packages/gunicorn/app/base.py", line 67, in wsgi
    self.callable = self.load()
  File "/usr/local/lib/python3.5/dist-packages/gunicorn/app/wsgiapp.py", line 49, in load
    return self.load_wsgiapp()
  File "/usr/local/lib/python3.5/dist-packages/gunicorn/app/wsgiapp.py", line 39, in load_wsgiapp
    return util.import_app(self.app_uri)
  File "/usr/local/lib/python3.5/dist-packages/gunicorn/util.py", line 331, in import_app
    mod = importlib.import_module(module)
  File "/usr/lib/python3.5/importlib/__init__.py", line 126, in import_module
    return _bootstrap._gcd_import(name[level:], package, level)
  File "<frozen importlib._bootstrap>", line 986, in _gcd_import
  File "<frozen importlib._bootstrap>", line 969, in _find_and_load
  File "<frozen importlib._bootstrap>", line 956, in _find_and_load_unlocked
ImportError: No module named 'server'
[2020-06-21 18:31:55 -0400] [15579] [INFO] Worker exiting (pid: 15579)
[2020-06-21 18:31:55 -0400] [15572] [INFO] Shutting down: Master
[2020-06-21 18:31:55 -0400] [15572] [INFO] Reason: Worker failed to boot.
/web/activities/mobileapps/run.sh: line 2: ../mobileapps/venv/bin/activate: No such file or directory
[2020-06-21 18:32:00 -0400] [15619] [INFO] Starting gunicorn 20.0.0
[2020-06-21 18:32:00 -0400] [15619] [INFO] Listening at: http://127.0.0.1:10831 (15619)
[2020-06-21 18:32:00 -0400] [15619] [INFO] Using worker: sync
[2020-06-21 18:32:00 -0400] [15627] [INFO] Booting worker with pid: 15627
[2020-06-21 18:32:00 -0400] [15627] [ERROR] Exception in worker process
Traceback (most recent call last):
  File "/usr/local/lib/python3.5/dist-packages/gunicorn/arbiter.py", line 583, in spawn_worker
    worker.init_process()
  File "/usr/local/lib/python3.5/dist-packages/gunicorn/workers/base.py", line 133, in init_process
    self.load_wsgi()
  File "/usr/local/lib/python3.5/dist-packages/gunicorn/workers/base.py", line 142, in load_wsgi
    self.wsgi = self.app.wsgi()
  File "/usr/local/lib/python3.5/dist-packages/gunicorn/app/base.py", line 67, in wsgi
    self.callable = self.load()
  File "/usr/local/lib/python3.5/dist-packages/gunicorn/app/wsgiapp.py", line 49, in load
    return self.load_wsgiapp()
  File "/usr/local/lib/python3.5/dist-packages/gunicorn/app/wsgiapp.py", line 39, in load_wsgiapp
    return util.import_app(self.app_uri)
  File "/usr/local/lib/python3.5/dist-packages/gunicorn/util.py", line 331, in import_app
    mod = importlib.import_module(module)
  File "/usr/lib/python3.5/importlib/__init__.py", line 126, in import_module
    return _bootstrap._gcd_import(name[level:], package, level)
  File "<frozen importlib._bootstrap>", line 986, in _gcd_import
  File "<frozen importlib._bootstrap>", line 969, in _find_and_load
  File "<frozen importlib._bootstrap>", line 956, in _find_and_load_unlocked
ImportError: No module named 'server'
[2020-06-21 18:32:00 -0400] [15627] [INFO] Worker exiting (pid: 15627)
[2020-06-21 18:32:00 -0400] [15619] [INFO] Shutting down: Master
[2020-06-21 18:32:00 -0400] [15619] [INFO] Reason: Worker failed to boot.
/web/activities/mobileapps/run.sh: line 2: ../mobileapps/venv/bin/activate: No such file or directory
[2020-06-21 18:32:02 -0400] [15803] [INFO] Starting gunicorn 20.0.0
[2020-06-21 18:32:02 -0400] [15803] [INFO] Listening at: http://127.0.0.1:10831 (15803)
[2020-06-21 18:32:02 -0400] [15803] [INFO] Using worker: sync
[2020-06-21 18:32:02 -0400] [15816] [INFO] Booting worker with pid: 15816
[2020-06-21 18:32:02 -0400] [15816] [ERROR] Exception in worker process
Traceback (most recent call last):
  File "/usr/local/lib/python3.5/dist-packages/gunicorn/arbiter.py", line 583, in spawn_worker
    worker.init_process()
  File "/usr/local/lib/python3.5/dist-packages/gunicorn/workers/base.py", line 133, in init_process
    self.load_wsgi()
  File "/usr/local/lib/python3.5/dist-packages/gunicorn/workers/base.py", line 142, in load_wsgi
    self.wsgi = self.app.wsgi()
  File "/usr/local/lib/python3.5/dist-packages/gunicorn/app/base.py", line 67, in wsgi
    self.callable = self.load()
  File "/usr/local/lib/python3.5/dist-packages/gunicorn/app/wsgiapp.py", line 49, in load
    return self.load_wsgiapp()
  File "/usr/local/lib/python3.5/dist-packages/gunicorn/app/wsgiapp.py", line 39, in load_wsgiapp
    return util.import_app(self.app_uri)
  File "/usr/local/lib/python3.5/dist-packages/gunicorn/util.py", line 331, in import_app
    mod = importlib.import_module(module)
  File "/usr/lib/python3.5/importlib/__init__.py", line 126, in import_module
    return _bootstrap._gcd_import(name[level:], package, level)
  File "<frozen importlib._bootstrap>", line 986, in _gcd_import
  File "<frozen importlib._bootstrap>", line 969, in _find_and_load
  File "<frozen importlib._bootstrap>", line 956, in _find_and_load_unlocked
ImportError: No module named 'server'
[2020-06-21 18:32:02 -0400] [15816] [INFO] Worker exiting (pid: 15816)
[2020-06-21 18:32:02 -0400] [15803] [INFO] Shutting down: Master
[2020-06-21 18:32:02 -0400] [15803] [INFO] Reason: Worker failed to boot.
/web/activities/mobileapps/run.sh: line 2: ../mobileapps/venv/bin/activate: No such file or directory
[2020-06-21 18:33:07 -0400] [16695] [INFO] Starting gunicorn 20.0.0
[2020-06-21 18:33:07 -0400] [16695] [INFO] Listening at: http://127.0.0.1:10831 (16695)
[2020-06-21 18:33:07 -0400] [16695] [INFO] Using worker: sync
[2020-06-21 18:33:07 -0400] [16702] [INFO] Booting worker with pid: 16702
[2020-06-21 18:33:07 -0400] [16702] [ERROR] Exception in worker process
Traceback (most recent call last):
  File "/usr/local/lib/python3.5/dist-packages/gunicorn/arbiter.py", line 583, in spawn_worker
    worker.init_process()
  File "/usr/local/lib/python3.5/dist-packages/gunicorn/workers/base.py", line 133, in init_process
    self.load_wsgi()
  File "/usr/local/lib/python3.5/dist-packages/gunicorn/workers/base.py", line 142, in load_wsgi
    self.wsgi = self.app.wsgi()
  File "/usr/local/lib/python3.5/dist-packages/gunicorn/app/base.py", line 67, in wsgi
    self.callable = self.load()
  File "/usr/local/lib/python3.5/dist-packages/gunicorn/app/wsgiapp.py", line 49, in load
    return self.load_wsgiapp()
  File "/usr/local/lib/python3.5/dist-packages/gunicorn/app/wsgiapp.py", line 39, in load_wsgiapp
    return util.import_app(self.app_uri)
  File "/usr/local/lib/python3.5/dist-packages/gunicorn/util.py", line 331, in import_app
    mod = importlib.import_module(module)
  File "/usr/lib/python3.5/importlib/__init__.py", line 126, in import_module
    return _bootstrap._gcd_import(name[level:], package, level)
  File "<frozen importlib._bootstrap>", line 986, in _gcd_import
  File "<frozen importlib._bootstrap>", line 969, in _find_and_load
  File "<frozen importlib._bootstrap>", line 956, in _find_and_load_unlocked
ImportError: No module named 'run'
[2020-06-21 18:33:07 -0400] [16702] [INFO] Worker exiting (pid: 16702)
[2020-06-21 18:33:07 -0400] [16695] [INFO] Shutting down: Master
[2020-06-21 18:33:07 -0400] [16695] [INFO] Reason: Worker failed to boot.
/web/activities/mobileapps/run.sh: line 2: ../mobileapps/venv/bin/activate: No such file or directory
[2020-06-21 18:33:10 -0400] [16736] [INFO] Starting gunicorn 20.0.0
[2020-06-21 18:33:10 -0400] [16736] [INFO] Listening at: http://127.0.0.1:10831 (16736)
[2020-06-21 18:33:10 -0400] [16736] [INFO] Using worker: sync
[2020-06-21 18:33:10 -0400] [16740] [INFO] Booting worker with pid: 16740
[2020-06-21 18:33:10 -0400] [16740] [ERROR] Exception in worker process
Traceback (most recent call last):
  File "/usr/local/lib/python3.5/dist-packages/gunicorn/arbiter.py", line 583, in spawn_worker
    worker.init_process()
  File "/usr/local/lib/python3.5/dist-packages/gunicorn/workers/base.py", line 133, in init_process
    self.load_wsgi()
  File "/usr/local/lib/python3.5/dist-packages/gunicorn/workers/base.py", line 142, in load_wsgi
    self.wsgi = self.app.wsgi()
  File "/usr/local/lib/python3.5/dist-packages/gunicorn/app/base.py", line 67, in wsgi
    self.callable = self.load()
  File "/usr/local/lib/python3.5/dist-packages/gunicorn/app/wsgiapp.py", line 49, in load
    return self.load_wsgiapp()
  File "/usr/local/lib/python3.5/dist-packages/gunicorn/app/wsgiapp.py", line 39, in load_wsgiapp
    return util.import_app(self.app_uri)
  File "/usr/local/lib/python3.5/dist-packages/gunicorn/util.py", line 331, in import_app
    mod = importlib.import_module(module)
  File "/usr/lib/python3.5/importlib/__init__.py", line 126, in import_module
    return _bootstrap._gcd_import(name[level:], package, level)
  File "<frozen importlib._bootstrap>", line 986, in _gcd_import
  File "<frozen importlib._bootstrap>", line 969, in _find_and_load
  File "<frozen importlib._bootstrap>", line 956, in _find_and_load_unlocked
ImportError: No module named 'run'
[2020-06-21 18:33:10 -0400] [16740] [INFO] Worker exiting (pid: 16740)
[2020-06-21 18:33:10 -0400] [16736] [INFO] Shutting down: Master
[2020-06-21 18:33:10 -0400] [16736] [INFO] Reason: Worker failed to boot.
/web/activities/mobileapps/run.sh: line 2: ../mobileapps/venv/bin/activate: No such file or directory
[2020-06-21 18:33:13 -0400] [16772] [INFO] Starting gunicorn 20.0.0
[2020-06-21 18:33:13 -0400] [16772] [INFO] Listening at: http://127.0.0.1:10831 (16772)
[2020-06-21 18:33:13 -0400] [16772] [INFO] Using worker: sync
[2020-06-21 18:33:13 -0400] [16780] [INFO] Booting worker with pid: 16780
[2020-06-21 18:33:13 -0400] [16780] [ERROR] Exception in worker process
Traceback (most recent call last):
  File "/usr/local/lib/python3.5/dist-packages/gunicorn/arbiter.py", line 583, in spawn_worker
    worker.init_process()
  File "/usr/local/lib/python3.5/dist-packages/gunicorn/workers/base.py", line 133, in init_process
    self.load_wsgi()
  File "/usr/local/lib/python3.5/dist-packages/gunicorn/workers/base.py", line 142, in load_wsgi
    self.wsgi = self.app.wsgi()
  File "/usr/local/lib/python3.5/dist-packages/gunicorn/app/base.py", line 67, in wsgi
    self.callable = self.load()
  File "/usr/local/lib/python3.5/dist-packages/gunicorn/app/wsgiapp.py", line 49, in load
    return self.load_wsgiapp()
  File "/usr/local/lib/python3.5/dist-packages/gunicorn/app/wsgiapp.py", line 39, in load_wsgiapp
    return util.import_app(self.app_uri)
  File "/usr/local/lib/python3.5/dist-packages/gunicorn/util.py", line 331, in import_app
    mod = importlib.import_module(module)
  File "/usr/lib/python3.5/importlib/__init__.py", line 126, in import_module
    return _bootstrap._gcd_import(name[level:], package, level)
  File "<frozen importlib._bootstrap>", line 986, in _gcd_import
  File "<frozen importlib._bootstrap>", line 969, in _find_and_load
  File "<frozen importlib._bootstrap>", line 956, in _find_and_load_unlocked
ImportError: No module named 'run'
[2020-06-21 18:33:13 -0400] [16780] [INFO] Worker exiting (pid: 16780)
[2020-06-21 18:33:13 -0400] [16772] [INFO] Shutting down: Master
[2020-06-21 18:33:13 -0400] [16772] [INFO] Reason: Worker failed to boot.
/web/activities/mobileapps/run.sh: line 2: ../mobileapps/venv/bin/activate: No such file or directory
[2020-06-21 18:33:18 -0400] [16814] [INFO] Starting gunicorn 20.0.0
[2020-06-21 18:33:18 -0400] [16814] [INFO] Listening at: http://127.0.0.1:10831 (16814)
[2020-06-21 18:33:18 -0400] [16814] [INFO] Using worker: sync
[2020-06-21 18:33:18 -0400] [16819] [INFO] Booting worker with pid: 16819
[2020-06-21 18:33:18 -0400] [16819] [ERROR] Exception in worker process
Traceback (most recent call last):
  File "/usr/local/lib/python3.5/dist-packages/gunicorn/arbiter.py", line 583, in spawn_worker
    worker.init_process()
  File "/usr/local/lib/python3.5/dist-packages/gunicorn/workers/base.py", line 133, in init_process
    self.load_wsgi()
  File "/usr/local/lib/python3.5/dist-packages/gunicorn/workers/base.py", line 142, in load_wsgi
    self.wsgi = self.app.wsgi()
  File "/usr/local/lib/python3.5/dist-packages/gunicorn/app/base.py", line 67, in wsgi
    self.callable = self.load()
  File "/usr/local/lib/python3.5/dist-packages/gunicorn/app/wsgiapp.py", line 49, in load
    return self.load_wsgiapp()
  File "/usr/local/lib/python3.5/dist-packages/gunicorn/app/wsgiapp.py", line 39, in load_wsgiapp
    return util.import_app(self.app_uri)
  File "/usr/local/lib/python3.5/dist-packages/gunicorn/util.py", line 331, in import_app
    mod = importlib.import_module(module)
  File "/usr/lib/python3.5/importlib/__init__.py", line 126, in import_module
    return _bootstrap._gcd_import(name[level:], package, level)
  File "<frozen importlib._bootstrap>", line 986, in _gcd_import
  File "<frozen importlib._bootstrap>", line 969, in _find_and_load
  File "<frozen importlib._bootstrap>", line 956, in _find_and_load_unlocked
ImportError: No module named 'run'
[2020-06-21 18:33:18 -0400] [16819] [INFO] Worker exiting (pid: 16819)
[2020-06-21 18:33:18 -0400] [16814] [INFO] Shutting down: Master
[2020-06-21 18:33:18 -0400] [16814] [INFO] Reason: Worker failed to boot.
/web/activities/mobileapps/run.sh: line 2: ../mobileapps/venv/bin/activate: No such file or directory
[2020-06-21 18:38:10 -0400] [21239] [INFO] Starting gunicorn 20.0.0
[2020-06-21 18:38:10 -0400] [21239] [INFO] Listening at: http://127.0.0.1:10831 (21239)
[2020-06-21 18:38:10 -0400] [21239] [INFO] Using worker: sync
[2020-06-21 18:38:10 -0400] [21245] [INFO] Booting worker with pid: 21245
 * Serving Flask app "app" (lazy loading)
 * Environment: production
   WARNING: Do not use the development server in a production environment.
   Use a production WSGI server instead.
 * Debug mode: on
[2020-06-21 18:38:10 -0400] [21245] [ERROR] Exception in worker process
Traceback (most recent call last):
  File "/usr/local/lib/python3.5/dist-packages/gunicorn/arbiter.py", line 583, in spawn_worker
    worker.init_process()
  File "/usr/local/lib/python3.5/dist-packages/gunicorn/workers/base.py", line 133, in init_process
    self.load_wsgi()
  File "/usr/local/lib/python3.5/dist-packages/gunicorn/workers/base.py", line 142, in load_wsgi
    self.wsgi = self.app.wsgi()
  File "/usr/local/lib/python3.5/dist-packages/gunicorn/app/base.py", line 67, in wsgi
    self.callable = self.load()
  File "/usr/local/lib/python3.5/dist-packages/gunicorn/app/wsgiapp.py", line 49, in load
    return self.load_wsgiapp()
  File "/usr/local/lib/python3.5/dist-packages/gunicorn/app/wsgiapp.py", line 39, in load_wsgiapp
    return util.import_app(self.app_uri)
  File "/usr/local/lib/python3.5/dist-packages/gunicorn/util.py", line 331, in import_app
    mod = importlib.import_module(module)
  File "/usr/lib/python3.5/importlib/__init__.py", line 126, in import_module
    return _bootstrap._gcd_import(name[level:], package, level)
  File "<frozen importlib._bootstrap>", line 986, in _gcd_import
  File "<frozen importlib._bootstrap>", line 969, in _find_and_load
  File "<frozen importlib._bootstrap>", line 958, in _find_and_load_unlocked
  File "<frozen importlib._bootstrap>", line 673, in _load_unlocked
  File "<frozen importlib._bootstrap_external>", line 665, in exec_module
  File "<frozen importlib._bootstrap>", line 222, in _call_with_frames_removed
  File "/web/activities/mobileapps/public/run.py", line 3, in <module>
    app.run(debug=True)
  File "/usr/local/lib/python3.5/dist-packages/flask/app.py", line 943, in run
    run_simple(host, port, self, **options)
  File "/usr/local/lib/python3.5/dist-packages/werkzeug/serving.py", line 795, in run_simple
    s.bind(get_sockaddr(hostname, port, address_family))
OSError: [Errno 98] Address already in use
[2020-06-21 18:38:11 -0400] [21245] [INFO] Worker exiting (pid: 21245)
[2020-06-21 18:38:11 -0400] [21239] [INFO] Shutting down: Master
[2020-06-21 18:38:11 -0400] [21239] [INFO] Reason: Worker failed to boot.
/web/activities/mobileapps/run.sh: line 2: ../mobileapps/venv/bin/activate: No such file or directory
[2020-06-21 18:38:13 -0400] [21276] [INFO] Starting gunicorn 20.0.0
[2020-06-21 18:38:13 -0400] [21276] [INFO] Listening at: http://127.0.0.1:10831 (21276)
[2020-06-21 18:38:13 -0400] [21276] [INFO] Using worker: sync
[2020-06-21 18:38:13 -0400] [21286] [INFO] Booting worker with pid: 21286
 * Serving Flask app "app" (lazy loading)
 * Environment: production
   WARNING: Do not use the development server in a production environment.
   Use a production WSGI server instead.
 * Debug mode: on
[2020-06-21 18:38:14 -0400] [21286] [ERROR] Exception in worker process
Traceback (most recent call last):
  File "/usr/local/lib/python3.5/dist-packages/gunicorn/arbiter.py", line 583, in spawn_worker
    worker.init_process()
  File "/usr/local/lib/python3.5/dist-packages/gunicorn/workers/base.py", line 133, in init_process
    self.load_wsgi()
  File "/usr/local/lib/python3.5/dist-packages/gunicorn/workers/base.py", line 142, in load_wsgi
    self.wsgi = self.app.wsgi()
  File "/usr/local/lib/python3.5/dist-packages/gunicorn/app/base.py", line 67, in wsgi
    self.callable = self.load()
  File "/usr/local/lib/python3.5/dist-packages/gunicorn/app/wsgiapp.py", line 49, in load
    return self.load_wsgiapp()
  File "/usr/local/lib/python3.5/dist-packages/gunicorn/app/wsgiapp.py", line 39, in load_wsgiapp
    return util.import_app(self.app_uri)
  File "/usr/local/lib/python3.5/dist-packages/gunicorn/util.py", line 331, in import_app
    mod = importlib.import_module(module)
  File "/usr/lib/python3.5/importlib/__init__.py", line 126, in import_module
    return _bootstrap._gcd_import(name[level:], package, level)
  File "<frozen importlib._bootstrap>", line 986, in _gcd_import
  File "<frozen importlib._bootstrap>", line 969, in _find_and_load
  File "<frozen importlib._bootstrap>", line 958, in _find_and_load_unlocked
  File "<frozen importlib._bootstrap>", line 673, in _load_unlocked
  File "<frozen importlib._bootstrap_external>", line 665, in exec_module
  File "<frozen importlib._bootstrap>", line 222, in _call_with_frames_removed
  File "/web/activities/mobileapps/public/run.py", line 3, in <module>
    app.run(debug=True)
  File "/usr/local/lib/python3.5/dist-packages/flask/app.py", line 943, in run
    run_simple(host, port, self, **options)
  File "/usr/local/lib/python3.5/dist-packages/werkzeug/serving.py", line 795, in run_simple
    s.bind(get_sockaddr(hostname, port, address_family))
OSError: [Errno 98] Address already in use
[2020-06-21 18:38:14 -0400] [21286] [INFO] Worker exiting (pid: 21286)
[2020-06-21 18:38:14 -0400] [21276] [INFO] Shutting down: Master
[2020-06-21 18:38:14 -0400] [21276] [INFO] Reason: Worker failed to boot.
/web/activities/mobileapps/run.sh: line 2: ../mobileapps/venv/bin/activate: No such file or directory
[2020-06-21 18:38:17 -0400] [21330] [INFO] Starting gunicorn 20.0.0
[2020-06-21 18:38:17 -0400] [21330] [INFO] Listening at: http://127.0.0.1:10831 (21330)
[2020-06-21 18:38:17 -0400] [21330] [INFO] Using worker: sync
[2020-06-21 18:38:17 -0400] [21334] [INFO] Booting worker with pid: 21334
 * Serving Flask app "app" (lazy loading)
 * Environment: production
   WARNING: Do not use the development server in a production environment.
   Use a production WSGI server instead.
 * Debug mode: on
[2020-06-21 18:38:17 -0400] [21334] [ERROR] Exception in worker process
Traceback (most recent call last):
  File "/usr/local/lib/python3.5/dist-packages/gunicorn/arbiter.py", line 583, in spawn_worker
    worker.init_process()
  File "/usr/local/lib/python3.5/dist-packages/gunicorn/workers/base.py", line 133, in init_process
    self.load_wsgi()
  File "/usr/local/lib/python3.5/dist-packages/gunicorn/workers/base.py", line 142, in load_wsgi
    self.wsgi = self.app.wsgi()
  File "/usr/local/lib/python3.5/dist-packages/gunicorn/app/base.py", line 67, in wsgi
    self.callable = self.load()
  File "/usr/local/lib/python3.5/dist-packages/gunicorn/app/wsgiapp.py", line 49, in load
    return self.load_wsgiapp()
  File "/usr/local/lib/python3.5/dist-packages/gunicorn/app/wsgiapp.py", line 39, in load_wsgiapp
    return util.import_app(self.app_uri)
  File "/usr/local/lib/python3.5/dist-packages/gunicorn/util.py", line 331, in import_app
    mod = importlib.import_module(module)
  File "/usr/lib/python3.5/importlib/__init__.py", line 126, in import_module
    return _bootstrap._gcd_import(name[level:], package, level)
  File "<frozen importlib._bootstrap>", line 986, in _gcd_import
  File "<frozen importlib._bootstrap>", line 969, in _find_and_load
  File "<frozen importlib._bootstrap>", line 958, in _find_and_load_unlocked
  File "<frozen importlib._bootstrap>", line 673, in _load_unlocked
  File "<frozen importlib._bootstrap_external>", line 665, in exec_module
  File "<frozen importlib._bootstrap>", line 222, in _call_with_frames_removed
  File "/web/activities/mobileapps/public/run.py", line 3, in <module>
    app.run(debug=True)
  File "/usr/local/lib/python3.5/dist-packages/flask/app.py", line 943, in run
    run_simple(host, port, self, **options)
  File "/usr/local/lib/python3.5/dist-packages/werkzeug/serving.py", line 795, in run_simple
    s.bind(get_sockaddr(hostname, port, address_family))
OSError: [Errno 98] Address already in use
[2020-06-21 18:38:17 -0400] [21334] [INFO] Worker exiting (pid: 21334)
[2020-06-21 18:38:18 -0400] [21330] [INFO] Shutting down: Master
[2020-06-21 18:38:18 -0400] [21330] [INFO] Reason: Worker failed to boot.
/web/activities/mobileapps/run.sh: line 2: ../mobileapps/venv/bin/activate: No such file or directory
[2020-06-21 18:38:22 -0400] [21371] [INFO] Starting gunicorn 20.0.0
[2020-06-21 18:38:22 -0400] [21371] [INFO] Listening at: http://127.0.0.1:10831 (21371)
[2020-06-21 18:38:22 -0400] [21371] [INFO] Using worker: sync
[2020-06-21 18:38:22 -0400] [21384] [INFO] Booting worker with pid: 21384
 * Serving Flask app "app" (lazy loading)
 * Environment: production
   WARNING: Do not use the development server in a production environment.
   Use a production WSGI server instead.
 * Debug mode: on
[2020-06-21 18:38:22 -0400] [21384] [ERROR] Exception in worker process
Traceback (most recent call last):
  File "/usr/local/lib/python3.5/dist-packages/gunicorn/arbiter.py", line 583, in spawn_worker
    worker.init_process()
  File "/usr/local/lib/python3.5/dist-packages/gunicorn/workers/base.py", line 133, in init_process
    self.load_wsgi()
  File "/usr/local/lib/python3.5/dist-packages/gunicorn/workers/base.py", line 142, in load_wsgi
    self.wsgi = self.app.wsgi()
  File "/usr/local/lib/python3.5/dist-packages/gunicorn/app/base.py", line 67, in wsgi
    self.callable = self.load()
  File "/usr/local/lib/python3.5/dist-packages/gunicorn/app/wsgiapp.py", line 49, in load
    return self.load_wsgiapp()
  File "/usr/local/lib/python3.5/dist-packages/gunicorn/app/wsgiapp.py", line 39, in load_wsgiapp
    return util.import_app(self.app_uri)
  File "/usr/local/lib/python3.5/dist-packages/gunicorn/util.py", line 331, in import_app
    mod = importlib.import_module(module)
  File "/usr/lib/python3.5/importlib/__init__.py", line 126, in import_module
    return _bootstrap._gcd_import(name[level:], package, level)
  File "<frozen importlib._bootstrap>", line 986, in _gcd_import
  File "<frozen importlib._bootstrap>", line 969, in _find_and_load
  File "<frozen importlib._bootstrap>", line 958, in _find_and_load_unlocked
  File "<frozen importlib._bootstrap>", line 673, in _load_unlocked
  File "<frozen importlib._bootstrap_external>", line 665, in exec_module
  File "<frozen importlib._bootstrap>", line 222, in _call_with_frames_removed
  File "/web/activities/mobileapps/public/run.py", line 3, in <module>
    app.run(debug=True)
  File "/usr/local/lib/python3.5/dist-packages/flask/app.py", line 943, in run
    run_simple(host, port, self, **options)
  File "/usr/local/lib/python3.5/dist-packages/werkzeug/serving.py", line 795, in run_simple
    s.bind(get_sockaddr(hostname, port, address_family))
OSError: [Errno 98] Address already in use
[2020-06-21 18:38:22 -0400] [21384] [INFO] Worker exiting (pid: 21384)
[2020-06-21 18:38:22 -0400] [21371] [INFO] Shutting down: Master
[2020-06-21 18:38:22 -0400] [21371] [INFO] Reason: Worker failed to boot.
/web/activities/mobileapps/run.sh: line 2: ../mobileapps/venv/bin/activate: No such file or directory
[2020-06-21 18:40:04 -0400] [22624] [INFO] Starting gunicorn 20.0.0
[2020-06-21 18:40:04 -0400] [22624] [INFO] Listening at: http://127.0.0.1:10831 (22624)
[2020-06-21 18:40:04 -0400] [22624] [INFO] Using worker: sync
[2020-06-21 18:40:04 -0400] [22629] [INFO] Booting worker with pid: 22629
 * Serving Flask app "app" (lazy loading)
 * Environment: production
   WARNING: Do not use the development server in a production environment.
   Use a production WSGI server instead.
 * Debug mode: off
[2020-06-21 18:40:04 -0400] [22629] [ERROR] Exception in worker process
Traceback (most recent call last):
  File "/usr/local/lib/python3.5/dist-packages/gunicorn/arbiter.py", line 583, in spawn_worker
    worker.init_process()
  File "/usr/local/lib/python3.5/dist-packages/gunicorn/workers/base.py", line 133, in init_process
    self.load_wsgi()
  File "/usr/local/lib/python3.5/dist-packages/gunicorn/workers/base.py", line 142, in load_wsgi
    self.wsgi = self.app.wsgi()
  File "/usr/local/lib/python3.5/dist-packages/gunicorn/app/base.py", line 67, in wsgi
    self.callable = self.load()
  File "/usr/local/lib/python3.5/dist-packages/gunicorn/app/wsgiapp.py", line 49, in load
    return self.load_wsgiapp()
  File "/usr/local/lib/python3.5/dist-packages/gunicorn/app/wsgiapp.py", line 39, in load_wsgiapp
    return util.import_app(self.app_uri)
  File "/usr/local/lib/python3.5/dist-packages/gunicorn/util.py", line 331, in import_app
    mod = importlib.import_module(module)
  File "/usr/lib/python3.5/importlib/__init__.py", line 126, in import_module
    return _bootstrap._gcd_import(name[level:], package, level)
  File "<frozen importlib._bootstrap>", line 986, in _gcd_import
  File "<frozen importlib._bootstrap>", line 969, in _find_and_load
  File "<frozen importlib._bootstrap>", line 958, in _find_and_load_unlocked
  File "<frozen importlib._bootstrap>", line 673, in _load_unlocked
  File "<frozen importlib._bootstrap_external>", line 665, in exec_module
  File "<frozen importlib._bootstrap>", line 222, in _call_with_frames_removed
  File "/web/activities/mobileapps/public/run.py", line 3, in <module>
    app.run()
  File "/usr/local/lib/python3.5/dist-packages/flask/app.py", line 943, in run
    run_simple(host, port, self, **options)
  File "/usr/local/lib/python3.5/dist-packages/werkzeug/serving.py", line 814, in run_simple
    inner()
  File "/usr/local/lib/python3.5/dist-packages/werkzeug/serving.py", line 774, in inner
    fd=fd)
  File "/usr/local/lib/python3.5/dist-packages/werkzeug/serving.py", line 660, in make_server
    passthrough_errors, ssl_context, fd=fd)
  File "/usr/local/lib/python3.5/dist-packages/werkzeug/serving.py", line 577, in __init__
    self.address_family), handler)
  File "/usr/lib/python3.5/socketserver.py", line 440, in __init__
    self.server_bind()
  File "/usr/lib/python3.5/http/server.py", line 138, in server_bind
    socketserver.TCPServer.server_bind(self)
  File "/usr/lib/python3.5/socketserver.py", line 454, in server_bind
    self.socket.bind(self.server_address)
OSError: [Errno 98] Address already in use
[2020-06-21 18:40:05 -0400] [22629] [INFO] Worker exiting (pid: 22629)
[2020-06-21 18:40:05 -0400] [22624] [INFO] Shutting down: Master
[2020-06-21 18:40:05 -0400] [22624] [INFO] Reason: Worker failed to boot.
/web/activities/mobileapps/run.sh: line 2: ../mobileapps/venv/bin/activate: No such file or directory
[2020-06-21 18:40:07 -0400] [22683] [INFO] Starting gunicorn 20.0.0
[2020-06-21 18:40:07 -0400] [22683] [INFO] Listening at: http://127.0.0.1:10831 (22683)
[2020-06-21 18:40:07 -0400] [22683] [INFO] Using worker: sync
[2020-06-21 18:40:07 -0400] [22698] [INFO] Booting worker with pid: 22698
 * Serving Flask app "app" (lazy loading)
 * Environment: production
   WARNING: Do not use the development server in a production environment.
   Use a production WSGI server instead.
 * Debug mode: off
[2020-06-21 18:40:07 -0400] [22698] [ERROR] Exception in worker process
Traceback (most recent call last):
  File "/usr/local/lib/python3.5/dist-packages/gunicorn/arbiter.py", line 583, in spawn_worker
    worker.init_process()
  File "/usr/local/lib/python3.5/dist-packages/gunicorn/workers/base.py", line 133, in init_process
    self.load_wsgi()
  File "/usr/local/lib/python3.5/dist-packages/gunicorn/workers/base.py", line 142, in load_wsgi
    self.wsgi = self.app.wsgi()
  File "/usr/local/lib/python3.5/dist-packages/gunicorn/app/base.py", line 67, in wsgi
    self.callable = self.load()
  File "/usr/local/lib/python3.5/dist-packages/gunicorn/app/wsgiapp.py", line 49, in load
    return self.load_wsgiapp()
  File "/usr/local/lib/python3.5/dist-packages/gunicorn/app/wsgiapp.py", line 39, in load_wsgiapp
    return util.import_app(self.app_uri)
  File "/usr/local/lib/python3.5/dist-packages/gunicorn/util.py", line 331, in import_app
    mod = importlib.import_module(module)
  File "/usr/lib/python3.5/importlib/__init__.py", line 126, in import_module
    return _bootstrap._gcd_import(name[level:], package, level)
  File "<frozen importlib._bootstrap>", line 986, in _gcd_import
  File "<frozen importlib._bootstrap>", line 969, in _find_and_load
  File "<frozen importlib._bootstrap>", line 958, in _find_and_load_unlocked
  File "<frozen importlib._bootstrap>", line 673, in _load_unlocked
  File "<frozen importlib._bootstrap_external>", line 665, in exec_module
  File "<frozen importlib._bootstrap>", line 222, in _call_with_frames_removed
  File "/web/activities/mobileapps/public/run.py", line 3, in <module>
    app.run()
  File "/usr/local/lib/python3.5/dist-packages/flask/app.py", line 943, in run
    run_simple(host, port, self, **options)
  File "/usr/local/lib/python3.5/dist-packages/werkzeug/serving.py", line 814, in run_simple
    inner()
  File "/usr/local/lib/python3.5/dist-packages/werkzeug/serving.py", line 774, in inner
    fd=fd)
  File "/usr/local/lib/python3.5/dist-packages/werkzeug/serving.py", line 660, in make_server
    passthrough_errors, ssl_context, fd=fd)
  File "/usr/local/lib/python3.5/dist-packages/werkzeug/serving.py", line 577, in __init__
    self.address_family), handler)
  File "/usr/lib/python3.5/socketserver.py", line 440, in __init__
    self.server_bind()
  File "/usr/lib/python3.5/http/server.py", line 138, in server_bind
    socketserver.TCPServer.server_bind(self)
  File "/usr/lib/python3.5/socketserver.py", line 454, in server_bind
    self.socket.bind(self.server_address)
OSError: [Errno 98] Address already in use
[2020-06-21 18:40:07 -0400] [22698] [INFO] Worker exiting (pid: 22698)
[2020-06-21 18:40:07 -0400] [22683] [INFO] Shutting down: Master
[2020-06-21 18:40:07 -0400] [22683] [INFO] Reason: Worker failed to boot.
/web/activities/mobileapps/run.sh: line 2: ../mobileapps/venv/bin/activate: No such file or directory
[2020-06-21 18:40:11 -0400] [22722] [INFO] Starting gunicorn 20.0.0
[2020-06-21 18:40:11 -0400] [22722] [INFO] Listening at: http://127.0.0.1:10831 (22722)
[2020-06-21 18:40:11 -0400] [22722] [INFO] Using worker: sync
[2020-06-21 18:40:11 -0400] [22735] [INFO] Booting worker with pid: 22735
 * Serving Flask app "app" (lazy loading)
 * Environment: production
   WARNING: Do not use the development server in a production environment.
   Use a production WSGI server instead.
 * Debug mode: off
[2020-06-21 18:40:11 -0400] [22735] [ERROR] Exception in worker process
Traceback (most recent call last):
  File "/usr/local/lib/python3.5/dist-packages/gunicorn/arbiter.py", line 583, in spawn_worker
    worker.init_process()
  File "/usr/local/lib/python3.5/dist-packages/gunicorn/workers/base.py", line 133, in init_process
    self.load_wsgi()
  File "/usr/local/lib/python3.5/dist-packages/gunicorn/workers/base.py", line 142, in load_wsgi
    self.wsgi = self.app.wsgi()
  File "/usr/local/lib/python3.5/dist-packages/gunicorn/app/base.py", line 67, in wsgi
    self.callable = self.load()
  File "/usr/local/lib/python3.5/dist-packages/gunicorn/app/wsgiapp.py", line 49, in load
    return self.load_wsgiapp()
  File "/usr/local/lib/python3.5/dist-packages/gunicorn/app/wsgiapp.py", line 39, in load_wsgiapp
    return util.import_app(self.app_uri)
  File "/usr/local/lib/python3.5/dist-packages/gunicorn/util.py", line 331, in import_app
    mod = importlib.import_module(module)
  File "/usr/lib/python3.5/importlib/__init__.py", line 126, in import_module
    return _bootstrap._gcd_import(name[level:], package, level)
  File "<frozen importlib._bootstrap>", line 986, in _gcd_import
  File "<frozen importlib._bootstrap>", line 969, in _find_and_load
  File "<frozen importlib._bootstrap>", line 958, in _find_and_load_unlocked
  File "<frozen importlib._bootstrap>", line 673, in _load_unlocked
  File "<frozen importlib._bootstrap_external>", line 665, in exec_module
  File "<frozen importlib._bootstrap>", line 222, in _call_with_frames_removed
  File "/web/activities/mobileapps/public/run.py", line 3, in <module>
    app.run()
  File "/usr/local/lib/python3.5/dist-packages/flask/app.py", line 943, in run
    run_simple(host, port, self, **options)
  File "/usr/local/lib/python3.5/dist-packages/werkzeug/serving.py", line 814, in run_simple
    inner()
  File "/usr/local/lib/python3.5/dist-packages/werkzeug/serving.py", line 774, in inner
    fd=fd)
  File "/usr/local/lib/python3.5/dist-packages/werkzeug/serving.py", line 660, in make_server
    passthrough_errors, ssl_context, fd=fd)
  File "/usr/local/lib/python3.5/dist-packages/werkzeug/serving.py", line 577, in __init__
    self.address_family), handler)
  File "/usr/lib/python3.5/socketserver.py", line 440, in __init__
    self.server_bind()
  File "/usr/lib/python3.5/http/server.py", line 138, in server_bind
    socketserver.TCPServer.server_bind(self)
  File "/usr/lib/python3.5/socketserver.py", line 454, in server_bind
    self.socket.bind(self.server_address)
OSError: [Errno 98] Address already in use
[2020-06-21 18:40:11 -0400] [22735] [INFO] Worker exiting (pid: 22735)
[2020-06-21 18:40:12 -0400] [22722] [INFO] Shutting down: Master
[2020-06-21 18:40:12 -0400] [22722] [INFO] Reason: Worker failed to boot.
/web/activities/mobileapps/run.sh: line 2: ../mobileapps/venv/bin/activate: No such file or directory
[2020-06-21 18:40:16 -0400] [22781] [INFO] Starting gunicorn 20.0.0
[2020-06-21 18:40:16 -0400] [22781] [INFO] Listening at: http://127.0.0.1:10831 (22781)
[2020-06-21 18:40:16 -0400] [22781] [INFO] Using worker: sync
[2020-06-21 18:40:16 -0400] [22790] [INFO] Booting worker with pid: 22790
 * Serving Flask app "app" (lazy loading)
 * Environment: production
   WARNING: Do not use the development server in a production environment.
   Use a production WSGI server instead.
 * Debug mode: off
[2020-06-21 18:40:16 -0400] [22790] [ERROR] Exception in worker process
Traceback (most recent call last):
  File "/usr/local/lib/python3.5/dist-packages/gunicorn/arbiter.py", line 583, in spawn_worker
    worker.init_process()
  File "/usr/local/lib/python3.5/dist-packages/gunicorn/workers/base.py", line 133, in init_process
    self.load_wsgi()
  File "/usr/local/lib/python3.5/dist-packages/gunicorn/workers/base.py", line 142, in load_wsgi
    self.wsgi = self.app.wsgi()
  File "/usr/local/lib/python3.5/dist-packages/gunicorn/app/base.py", line 67, in wsgi
    self.callable = self.load()
  File "/usr/local/lib/python3.5/dist-packages/gunicorn/app/wsgiapp.py", line 49, in load
    return self.load_wsgiapp()
  File "/usr/local/lib/python3.5/dist-packages/gunicorn/app/wsgiapp.py", line 39, in load_wsgiapp
    return util.import_app(self.app_uri)
  File "/usr/local/lib/python3.5/dist-packages/gunicorn/util.py", line 331, in import_app
    mod = importlib.import_module(module)
  File "/usr/lib/python3.5/importlib/__init__.py", line 126, in import_module
    return _bootstrap._gcd_import(name[level:], package, level)
  File "<frozen importlib._bootstrap>", line 986, in _gcd_import
  File "<frozen importlib._bootstrap>", line 969, in _find_and_load
  File "<frozen importlib._bootstrap>", line 958, in _find_and_load_unlocked
  File "<frozen importlib._bootstrap>", line 673, in _load_unlocked
  File "<frozen importlib._bootstrap_external>", line 665, in exec_module
  File "<frozen importlib._bootstrap>", line 222, in _call_with_frames_removed
  File "/web/activities/mobileapps/public/run.py", line 3, in <module>
    app.run()
  File "/usr/local/lib/python3.5/dist-packages/flask/app.py", line 943, in run
    run_simple(host, port, self, **options)
  File "/usr/local/lib/python3.5/dist-packages/werkzeug/serving.py", line 814, in run_simple
    inner()
  File "/usr/local/lib/python3.5/dist-packages/werkzeug/serving.py", line 774, in inner
    fd=fd)
  File "/usr/local/lib/python3.5/dist-packages/werkzeug/serving.py", line 660, in make_server
    passthrough_errors, ssl_context, fd=fd)
  File "/usr/local/lib/python3.5/dist-packages/werkzeug/serving.py", line 577, in __init__
    self.address_family), handler)
  File "/usr/lib/python3.5/socketserver.py", line 440, in __init__
    self.server_bind()
  File "/usr/lib/python3.5/http/server.py", line 138, in server_bind
    socketserver.TCPServer.server_bind(self)
  File "/usr/lib/python3.5/socketserver.py", line 454, in server_bind
    self.socket.bind(self.server_address)
OSError: [Errno 98] Address already in use
[2020-06-21 18:40:16 -0400] [22790] [INFO] Worker exiting (pid: 22790)
[2020-06-21 18:40:16 -0400] [22781] [INFO] Shutting down: Master
[2020-06-21 18:40:16 -0400] [22781] [INFO] Reason: Worker failed to boot.
/web/activities/mobileapps/run.sh: line 2: ../mobileapps/venv/bin/activate: No such file or directory
[2020-06-21 18:49:31 -0400] [29351] [INFO] Starting gunicorn 20.0.0
[2020-06-21 18:49:31 -0400] [29351] [INFO] Listening at: http://127.0.0.1:10831 (29351)
[2020-06-21 18:49:31 -0400] [29351] [INFO] Using worker: sync
[2020-06-21 18:49:31 -0400] [29356] [INFO] Booting worker with pid: 29356
[2020-06-21 18:49:41 -0400] [29356] [INFO] Worker exiting (pid: 29356)
[2020-06-21 18:49:41 -0400] [29351] [INFO] Handling signal: term
/web/activities/mobileapps/run.sh: line 2: ../mobileapps/venv/bin/activate: No such file or directory
[2020-06-21 18:49:43 -0400] [29460] [INFO] Starting gunicorn 20.0.0
[2020-06-21 18:49:43 -0400] [29460] [INFO] Listening at: http://127.0.0.1:10831 (29460)
[2020-06-21 18:49:43 -0400] [29460] [INFO] Using worker: sync
[2020-06-21 18:49:43 -0400] [29475] [INFO] Booting worker with pid: 29475
[2020-06-21 18:49:54 -0400] [29460] [INFO] Handling signal: term
[2020-06-21 18:49:54 -0400] [29475] [INFO] Worker exiting (pid: 29475)
/web/activities/mobileapps/run.sh: line 2: ../mobileapps/venv/bin/activate: No such file or directory
[2020-06-21 18:49:56 -0400] [29667] [INFO] Starting gunicorn 20.0.0
[2020-06-21 18:49:56 -0400] [29667] [INFO] Listening at: http://127.0.0.1:10831 (29667)
[2020-06-21 18:49:56 -0400] [29667] [INFO] Using worker: sync
[2020-06-21 18:49:56 -0400] [29671] [INFO] Booting worker with pid: 29671
